Workbook
Name Slicer_Category: #N/A
Name Slicer_Category1: #N/A
Name Slicer_Category2: #N/A
Name Slicer_Segment: #N/A
Name Slicer_Segment1: #N/A
Name Slicer_Segment2: #N/A
Name Slicer_Ship_Mode: #N/A
Name Source: #REF!

Sheet Dashboard 
C14: Sub Category | D14: 2016 | E14: 2017 | F14: vs PY | I14: Sub Category | J14: 2016 | K14: 2017 | L14: vs PY | O14: Sub Category | P14: 2016 | Q14: 2017 | R14: vs PY | U14: Sub Category | V14: 2016 | W14: 2017 | X14: vs PY
C15: {=IF('Backend Work'!$A$11:$A$20="","",'Backend Work'!$A$11:$A$20)} -> Chairs | D15: {=IF('Backend Work'!$B$11:$B$20="","",'Backend Work'!$B$11:$B$20)} -> 83918.645 | E15: {=IF('Backend Work'!$C$11:$C$20="","",'Backend Work'!$C$11:$C$20)} -> 95554.353 | F15: =IF(C15="","",E15/D15-1) -> 0.13865462 | I15: {=IF('Backend Work'!$F$11:$F$20="","",'Backend Work'!$F$11:$F$20)} -> Chicago | J15: {=IF('Backend Work'!$G$11:$G$20="","",'Backend Work'!$G$11:$G$20)} -> 13067.55 | K15: {=IF('Backend Work'!$H$11:$H$20="","",'Backend Work'!$H$11:$H$20)} -> 16245.611 | L15: =IF(I15="","",K15/J15-1) -> 0.24320251 | O15: {=IF('Backend Work'!$A$27:$A$36="","",'Backend Work'!$A$27:$A$36)} -> Chairs | P15: {=IF('Backend Work'!$B$27:$B$36="","",'Backend Work'!$B$27:$B$36)} -> 83918.645 | Q15: {=IF('Backend Work'!$C$27:$C$36="","",'Backend Work'!$C$27:$C$36)} -> 95554.353 | R15: =IF(O15="","",Q15/P15-1) -> 0.13865462 | U15: {=IF('Backend Work'!$F$27:$F$36="","",'Backend Work'!$F$27:$F$36)} -> Chicago | V15: {='Backend Work'!$G$27:$G$36} -> 13067.55 | W15: {='Backend Work'!$H$27:$H$36} -> 16245.611 | X15: =IF(U15="","",W15/V15-1) -> 0.24320251
C16: Phones | D16: 78962.03 | E16: 105340.52 | F16: =IF(C16="","",E16/D16-1) -> 0.33406545 | I16: Los Angeles | J16: 56398.748 | K16: 48875.692 | L16: =IF(I16="","",K16/J16-1) -> -0.13339047 | O16: Phones | P16: 78962.03 | Q16: 105340.52 | R16: =IF(O16="","",Q16/P16-1) -> 0.33406545 | U16: Columbus | V16: 9506.412 | W16: 17571.473 | X16: =IF(U16="","",W16/V16-1) -> 0.84838118
C17: Tables | D17: 60833.2 | E17: 60893.543 | F17: =IF(C17="","",E17/D17-1) -> 0.00099192545 | I17: New York City | J17: 54824.098 | K17: 86939.601 | L17: =IF(I17="","",K17/J17-1) -> 0.58579173 | O17: Tables | P17: 60833.2 | Q17: 60893.543 | R17: =IF(O17="","",Q17/P17-1) -> 0.00099192545 | U17: Detroit | V17: 21197.32 | W17: 12148.886 | X17: =IF(U17="","",W17/V17-1) -> -0.42686689
C18: Storage | D18: 58788.7 | E18: 69677.618 | F18: =IF(C18="","",E18/D18-1) -> 0.18522128 | I18: Philadelphia | J18: 30304.938 | K18: 41595.502 | L18: =IF(I18="","",K18/J18-1) -> 0.37256516 | O18: Storage | P18: 58788.7 | Q18: 69677.618 | R18: =IF(O18="","",Q18/P18-1) -> 0.18522128 | U18: Houston | V18: 16448.681 | W18: 16212.806 | X18: =IF(U18="","",W18/V18-1) -> -0.014340055
C19: Machines | D19: 55906.886 | E19: 43544.675 | F19: =IF(C19="","",E19/D19-1) -> -0.22112144 | I19: San Francisco | J19: 29845.871 | K19: 37197.551 | L19: =IF(I19="","",K19/J19-1) -> 0.24632151 | O19: Machines | P19: 55906.886 | Q19: 43544.675 | R19: =IF(O19="","",Q19/P19-1) -> -0.22112144 | U19: Lafayette | V19: 18431.34 | W19: 5630.51 | X19: =IF(U19="","",W19/V19-1) -> -0.69451434
C20: Binders | D20: 49683.325 | E20: 72788.045 | F20: =IF(C20="","",E20/D20-1) -> 0.46503973 | I20: Seattle | J20: 16158.722 | K20: 56990.82 | L20: =IF(I20="","",K20/J20-1) -> 2.5269386 | O20: Binders | P20: 49683.325 | Q20: 72788.045 | R20: =IF(O20="","",Q20/P20-1) -> 0.46503973 | U20: Los Angeles | V20: 56398.748 | W20: 48875.692 | X20: =IF(U20="","",W20/V20-1) -> -0.13339047
C21: Copiers | D21: 49599.41 | E21: 62899.388 | F21: =IF(C21="","",E21/D21-1) -> 0.26814791 | I21: Columbus | J21: 9506.412 | K21: 17571.473 | L21: =IF(I21="","",K21/J21-1) -> 0.84838118 | O21: Copiers | P21: 49599.41 | Q21: 62899.388 | R21: =IF(O21="","",Q21/P21-1) -> 0.26814791 | U21: New York City | V21: 54824.098 | W21: 86939.601 | X21: =IF(U21="","",W21/V21-1) -> 0.58579173
C22: Accessories | D22: 41895.854 | E22: 59946.232 | F22: =IF(C22="","",E22/D22-1) -> 0.43083924 | I22: Detroit | J22: 21197.32 | K22: 12148.886 | L22: =IF(I22="","",K22/J22-1) -> -0.42686689 | O22: Accessories | P22: 41895.854 | Q22: 59946.232 | R22: =IF(O22="","",Q22/P22-1) -> 0.43083924 | U22: Philadelphia | V22: 30304.938 | W22: 41595.502 | X22: =IF(U22="","",W22/V22-1) -> 0.37256516
C23: Furnishings | D23: 27874.124 | E23: 28915.094 | F23: =IF(C23="","",E23/D23-1) -> 0.037345389 | I23: Houston | J23: 16448.681 | K23: 16212.806 | L23: =IF(I23="","",K23/J23-1) -> -0.014340055 | O23: Furnishings | P23: 27874.124 | Q23: 28915.094 | R23: =IF(O23="","",Q23/P23-1) -> 0.037345389 | U23: San Francisco | V23: 29845.871 | W23: 37197.551 | X23: =IF(U23="","",W23/V23-1) -> 0.24632151
C24: Appliances | D24: 26050.315 | E24: 42926.932 | F24: =IF(C24="","",E24/D24-1) -> 0.64784695 | I24: Lafayette | J24: 18431.34 | K24: 5630.51 | L24: =IF(I24="","",K24/J24-1) -> -0.69451434 | O24: Appliances | P24: 26050.315 | Q24: 42926.932 | R24: =IF(O24="","",Q24/P24-1) -> 0.64784695 | U24: Seattle | V24: 16158.722 | W24: 56990.82 | X24: =IF(U24="","",W24/V24-1) -> 2.5269386
C25: Total | D25: =SUM(_xlfn.ANCHORARRAY(D15)) -> 533512.49 | E25: =SUM(_xlfn.ANCHORARRAY(E15)) -> 642486.4 | F25: =IF(C25="","",E25/D25-1) -> 0.20425746 | I25: Total | J25: =SUM(_xlfn.ANCHORARRAY(J15)) -> 266183.68 | K25: =SUM(_xlfn.ANCHORARRAY(K15)) -> 339408.45 | L25: =IF(I25="","",K25/J25-1) -> 0.27509114 | O25: Total | P25: =SUM(_xlfn.ANCHORARRAY(P15)) -> 533512.49 | Q25: =SUM(_xlfn.ANCHORARRAY(Q15)) -> 642486.4 | R25: =IF(O25="","",Q25/P25-1) -> 0.20425746 | U25: Total | V25: =SUM(_xlfn.ANCHORARRAY(V15)) -> 266183.68 | W25: =SUM(_xlfn.ANCHORARRAY(W15)) -> 339408.45 | X25: =IF(U25="","",W25/V25-1) -> 0.27509114

Sheet Backend Work
A1: Row Labels | B1: Sum of Sales | C1: Sum of Profit | E1: Sales vs PY | F1: Profit vs PY
A2: 2016 | B2: 609205.6 | C2: 81795.174
A3: 2017 | B3: 733215.26 | C3: 93439.27 | E3: =B3/B2-1 -> 0.20355962 | F3: =C3/C2-1 -> 0.14235675
A4: Grand Total | B4: 1342420.9 | C4: 175234.44
A9: Sum of Sales | B9: Column Labels | F9: Sum of Sales | G9: Column Labels
A10: Row Labels | B10: 2016 | C10: 2017 | F10: Row Labels | G10: 2016 | H10: 2017
A11: Chairs | B11: 83918.645 | C11: 95554.353 | F11: Chicago | G11: 13067.55 | H11: 16245.611
A12: Phones | B12: 78962.03 | C12: 105340.52 | F12: Los Angeles | G12: 56398.748 | H12: 48875.692
A13: Tables | B13: 60833.2 | C13: 60893.543 | F13: New York City | G13: 54824.098 | H13: 86939.601
A14: Storage | B14: 58788.7 | C14: 69677.618 | F14: Philadelphia | G14: 30304.938 | H14: 41595.502
A15: Machines | B15: 55906.886 | C15: 43544.675 | F15: San Francisco | G15: 29845.871 | H15: 37197.551
A16: Binders | B16: 49683.325 | C16: 72788.045 | F16: Seattle | G16: 16158.722 | H16: 56990.82
A17: Copiers | B17: 49599.41 | C17: 62899.388 | F17: Columbus | G17: 9506.412 | H17: 17571.473
A18: Accessories | B18: 41895.854 | C18: 59946.232 | F18: Detroit | G18: 21197.32 | H18: 12148.886
A19: Furnishings | B19: 27874.124 | C19: 28915.094 | F19: Houston | G19: 16448.681 | H19: 16212.806
A20: Appliances | B20: 26050.315 | C20: 42926.932 | F20: Lafayette | G20: 18431.34 | H20: 5630.51
A25: Sum of Sales | B25: Column Labels | F25: Sum of Sales | G25: Column Labels
A26: Row Labels | B26: 2016 | C26: 2017 | F26: Row Labels | G26: 2016 | H26: 2017
A27: Chairs | B27: 83918.645 | C27: 95554.353 | F27: Chicago | G27: 13067.55 | H27: 16245.611
A28: Phones | B28: 78962.03 | C28: 105340.52 | F28: Columbus | G28: 9506.412 | H28: 17571.473
A29: Tables | B29: 60833.2 | C29: 60893.543 | F29: Detroit | G29: 21197.32 | H29: 12148.886
A30: Storage | B30: 58788.7 | C30: 69677.618 | F30: Houston | G30: 16448.681 | H30: 16212.806
A31: Machines | B31: 55906.886 | C31: 43544.675 | F31: Lafayette | G31: 18431.34 | H31: 5630.51
A32: Binders | B32: 49683.325 | C32: 72788.045 | F32: Los Angeles | G32: 56398.748 | H32: 48875.692
A33: Copiers | B33: 49599.41 | C33: 62899.388 | F33: New York City | G33: 54824.098 | H33: 86939.601
A34: Accessories | B34: 41895.854 | C34: 59946.232 | F34: Philadelphia | G34: 30304.938 | H34: 41595.502
A35: Furnishings | B35: 27874.124 | C35: 28915.094 | F35: San Francisco | G35: 29845.871 | H35: 37197.551
A36: Appliances | B36: 26050.315 | C36: 42926.932 | F36: Seattle | G36: 16158.722 | H36: 56990.82
A41: Order Date (Year) | B41: Order Date (Quarter) | C41: Sum of Sales | D41: Sum of Quantity | I41: Price
A42: 2014 | B42: Qtr1 | C42: 74447.796 | D42: 1028 | F42: =A42 -> 2014 | G42: =B42 -> Qtr1 | H42: =C42 -> 74447.796 | I42: =H42/D42 -> 72.420035
B43: Qtr2 | C43: 86538.76 | D43: 1523 | G43: =B43 -> Qtr2 | H43: =C43 -> 86538.76 | I43: =H43/D43 -> 56.821247
B44: Qtr3 | C44: 143633.21 | D44: 2159 | G44: =B44 -> Qtr3 | H44: =C44 -> 143633.21 | I44: =H44/D44 -> 66.527657
B45: Qtr4 | C45: 179627.73 | D45: 2871 | G45: =B45 -> Qtr4 | H45: =C45 -> 179627.73 | I45: =H45/D45 -> 62.566259
A46: 2015 | B46: Qtr1 | C46: 68851.739 | D46: 990 | F46: =A46 -> 2015 | G46: =B46 -> Qtr1 | H46: =C46 -> 68851.739 | I46: =H46/D46 -> 69.547211
B47: Qtr2 | C47: 89124.187 | D47: 1604 | G47: =B47 -> Qtr2 | H47: =C47 -> 89124.187 | I47: =H47/D47 -> 55.563708
B48: Qtr3 | C48: 130259.58 | D48: 2241 | G48: =B48 -> Qtr3 | H48: =C48 -> 130259.58 | I48: =H48/D48 -> 58.125647
B49: Qtr4 | C49: 182297.01 | D49: 3144 | G49: =B49 -> Qtr4 | H49: =C49 -> 182297.01 | I49: =H49/D49 -> 57.982509
A50: 2016 | B50: Qtr1 | C50: 93237.181 | D50: 1243 | F50: =A50 -> 2016 | G50: =B50 -> Qtr1 | H50: =C50 -> 93237.181 | I50: =H50/D50 -> 75.0098
B51: Qtr2 | C51: 136082.3 | D51: 2240 | G51: =B51 -> Qtr2 | H51: =C51 -> 136082.3 | I51: =H51/D51 -> 60.751027
B52: Qtr3 | C52: 143787.36 | D52: 2767 | G52: =B52 -> Qtr3 | H52: =C52 -> 143787.36 | I52: =H52/D52 -> 51.965075
...
